<robot
  name="my_robot">
  <link
    name="base">
    <inertial>
      <origin
        xyz="0.000204907436500964 -0.0023073240712552 0.0256355181704067"
        rpy="0 0 0" />
      <mass
        value="0.349087763378245" />
      <inertia
        ixx="0"
        ixy="0"
        ixz="0"
        iyy="0"
        iyz="0"
        izz="0" />
    </inertial>
    <visual>
      <origin
        xyz="0 0 0"
        rpy="0 0 0" />
      <geometry>
        <mesh
          filename="package://my_robot/meshes/base.STL" />
      </geometry>
      <material
        name="">
        <color
          rgba="0.792156862745098 0.819607843137255 0.933333333333333 1" />
      </material>
    </visual>
    <collision>
      <origin
        xyz="0 0 0"
        rpy="0 0 0" />
      <geometry>
        <mesh
          filename="package://my_robot/meshes/base.STL" />
      </geometry>
    </collision>
  </link>
  <link
    name="LF_HIP">
    <inertial>
      <origin
        xyz="-0.00594729168458417 -0.00485654837417016 -0.0202742503665817"
        rpy="0 0 0" />
      <mass
        value="0.0202222434753155" />
      <inertia
        ixx="8.20626267007156E-07"
        ixy="-1.59123300304472E-07"
        ixz="-1.48803220510119E-08"
        iyy="5.25729912696779E-07"
        iyz="-5.66988572550977E-08"
        izz="8.15355060430567E-07" />
    </inertial>
    <visual>
      <origin
        xyz="0 0 0"
        rpy="0 0 0" />
      <geometry>
        <mesh
          filename="package://my_robot/meshes/LF_HIP.STL" />
      </geometry>
      <material
        name="">
        <color
          rgba="0.792156862745098 0.819607843137255 0.933333333333333 1" />
      </material>
    </visual>
    <collision>
      <origin
        xyz="0 0 0"
        rpy="0 0 0" />
      <geometry>
        <mesh
          filename="package://my_robot/meshes/LF_HIP.STL" />
      </geometry>
    </collision>
  </link>
  <joint
    name="LF_HAA"
    type="revolute">
    <origin
      xyz="0.050205 -0.060264 0.0044408"
      rpy="1.5708 0 3.1416" />
    <parent
      link="base" />
    <child
      link="LF_HIP" />
    <axis
      xyz="0 0 -1" />
    <limit
      lower="-0.35"
      upper="0.35"
      effort="0"
      velocity="0" />
  </joint>
  <link
    name="LF_SHANK">
    <inertial>
      <origin
        xyz="-0.01216951489415 -0.030019682431949 -0.0224095204785165"
        rpy="0 0 0" />
      <mass
        value="0.0125650044620547" />
      <inertia
        ixx="0"
        ixy="0"
        ixz="0"
        iyy="0"
        iyz="0"
        izz="0" />
    </inertial>
    <visual>
      <origin
        xyz="0 0 0"
        rpy="0 0 0" />
      <geometry>
        <mesh
          filename="package://my_robot/meshes/LF_SHANK.STL" />
      </geometry>
      <material
        name="">
        <color
          rgba="0.792156862745098 0.819607843137255 0.933333333333333 1" />
      </material>
    </visual>
    <collision>
      <origin
        xyz="0 0 0"
        rpy="0 0 0" />
      <geometry>
        <mesh
          filename="package://my_robot/meshes/LF_SHANK.STL" />
      </geometry>
    </collision>
  </link>
  <joint
    name="LF_HFE"
    type="revolute">
    <origin
      xyz="0.015495 -0.011839 -0.0263"
      rpy="0.016319 1.5708 0" />
    <parent
      link="LF_HIP" />
    <child
      link="LF_SHANK" />
    <axis
      xyz="0 0 -1" />
    <limit
      lower="-0.524"
      upper="0.524"
      effort="0"
      velocity="0" />
  </joint>
  <link
    name="LF_KNEE">
    <inertial>
      <origin
        xyz="-0.0028475899665497 -0.0215718533675847 -0.0213998801293673"
        rpy="0 0 0" />
      <mass
        value="0.020940214536888" />
      <inertia
        ixx="2.84887560923765E-06"
        ixy="-4.57449680652954E-07"
        ixz="6.47675375288013E-08"
        iyy="2.88411284184737E-07"
        iyz="3.87108439912418E-07"
        izz="2.72321747739394E-06" />
    </inertial>
    <visual>
      <origin
        xyz="0 0 0"
        rpy="0 0 0" />
      <geometry>
        <mesh
          filename="package://my_robot/meshes/LF_KNEE.STL" />
      </geometry>
      <material
        name="">
        <color
          rgba="0.792156862745098 0.819607843137255 0.933333333333333 1" />
      </material>
    </visual>
    <collision>
      <origin
        xyz="0 0 0"
        rpy="0 0 0" />
      <geometry>
        <mesh
          filename="package://my_robot/meshes/LF_KNEE.STL" />
      </geometry>
    </collision>
  </link>
  <joint
    name="LF_KFE"
    type="revolute">
    <origin
      xyz="-0.024219 -0.060319 0"
      rpy="-1.7731E-18 5.103E-18 0.8858" />
    <parent
      link="LF_SHANK" />
    <child
      link="LF_KNEE" />
    <axis
      xyz="0 0 -1" />
    <limit
      lower="-0.524"
      upper="0.524"
      effort="0"
      velocity="0" />
  </joint>
  <link
    name="LH_HIP">
    <inertial>
      <origin
        xyz="-0.00594728603487756 -0.00485654703619716 -0.0202742474323915"
        rpy="0 0 0" />
      <mass
        value="0.0202222345780056" />
      <inertia
        ixx="8.20626247865029E-07"
        ixy="-1.59123036427776E-07"
        ixz="-1.48799410996211E-08"
        iyy="5.25728784115556E-07"
        iyz="-5.66984902989942E-08"
        izz="8.1535416831994E-07" />
    </inertial>
    <visual>
      <origin
        xyz="0 0 0"
        rpy="0 0 0" />
      <geometry>
        <mesh
          filename="package://my_robot/meshes/LH_HIP.STL" />
      </geometry>
      <material
        name="">
        <color
          rgba="0.792156862745098 0.819607843137255 0.933333333333333 1" />
      </material>
    </visual>
    <collision>
      <origin
        xyz="0 0 0"
        rpy="0 0 0" />
      <geometry>
        <mesh
          filename="package://my_robot/meshes/LH_HIP.STL" />
      </geometry>
    </collision>
  </link>
  <joint
    name="LH_HAA"
    type="revolute">
    <origin
      xyz="0.050205 0.096286 0.0044408"
      rpy="1.5708 0 3.1416" />
    <parent
      link="base" />
    <child
      link="LH_HIP" />
    <axis
      xyz="0 0 -1" />
    <limit
      lower="-0.35"
      upper="0.35"
      effort="0"
      velocity="0" />
  </joint>
  <link
    name="LH_SHANK">
    <inertial>
      <origin
        xyz="-0.01216951489415 -0.030019682431949 -0.0224095204785166"
        rpy="0 0 0" />
      <mass
        value="0.0125650044620547" />
      <inertia
        ixx="0"
        ixy="0"
        ixz="0"
        iyy="0"
        iyz="0"
        izz="0" />
    </inertial>
    <visual>
      <origin
        xyz="0 0 0"
        rpy="0 0 0" />
      <geometry>
        <mesh
          filename="package://my_robot/meshes/LH_SHANK.STL" />
      </geometry>
      <material
        name="">
        <color
          rgba="0.792156862745098 0.819607843137255 0.933333333333333 1" />
      </material>
    </visual>
    <collision>
      <origin
        xyz="0 0 0"
        rpy="0 0 0" />
      <geometry>
        <mesh
          filename="package://my_robot/meshes/LH_SHANK.STL" />
      </geometry>
    </collision>
  </link>
  <joint
    name="LH_HFE"
    type="revolute">
    <origin
      xyz="0.015495 -0.011839 -0.0263"
      rpy="0.016319 1.5708 0" />
    <parent
      link="LH_HIP" />
    <child
      link="LH_SHANK" />
    <axis
      xyz="0 0 -1" />
    <limit
      lower="-0.524"
      upper="0.524"
      effort="0"
      velocity="0" />
  </joint>
  <link
    name="LH_KNEE">
    <inertial>
      <origin
        xyz="-0.00284758887121367 -0.0215718639059826 -0.0213998748760903"
        rpy="0 0 0" />
      <mass
        value="0.0209402035630598" />
      <inertia
        ixx="2.84887018830337E-06"
        ixy="-4.57449976542861E-07"
        ixz="6.47677293463717E-08"
        iyy="2.88410414052883E-07"
        iyz="3.87106256854168E-07"
        izz="2.72321336151687E-06" />
    </inertial>
    <visual>
      <origin
        xyz="0 0 0"
        rpy="0 0 0" />
      <geometry>
        <mesh
          filename="package://my_robot/meshes/LH_KNEE.STL" />
      </geometry>
      <material
        name="">
        <color
          rgba="0.792156862745098 0.819607843137255 0.933333333333333 1" />
      </material>
    </visual>
    <collision>
      <origin
        xyz="0 0 0"
        rpy="0 0 0" />
      <geometry>
        <mesh
          filename="package://my_robot/meshes/LH_KNEE.STL" />
      </geometry>
    </collision>
  </link>
  <joint
    name="LH_KFE"
    type="revolute">
    <origin
      xyz="-0.024219 -0.060319 0"
      rpy="4.6201E-19 1.8952E-18 0.8858" />
    <parent
      link="LH_SHANK" />
    <child
      link="LH_KNEE" />
    <axis
      xyz="0 0 -1" />
    <limit
      lower="-0.524"
      upper="0.524"
      effort="0"
      velocity="0" />
  </joint>
  <link
    name="RH_HIP">
    <inertial>
      <origin
        xyz="-0.00610260953118668 -0.00465988369827438 -0.0202742545501112"
        rpy="0 0 0" />
      <mass
        value="0.0202222328718557" />
      <inertia
        ixx="8.09931421912782E-07"
        ixy="-1.6840225690398E-07"
        ixz="-1.67219458209233E-08"
        iyy="5.36422285737063E-07"
        iyz="-5.61828884566937E-08"
        izz="8.15354851652084E-07" />
    </inertial>
    <visual>
      <origin
        xyz="0 0 0"
        rpy="0 0 0" />
      <geometry>
        <mesh
          filename="package://my_robot/meshes/RH_HIP.STL" />
      </geometry>
      <material
        name="">
        <color
          rgba="0.792156862745098 0.819607843137255 0.933333333333333 1" />
      </material>
    </visual>
    <collision>
      <origin
        xyz="0 0 0"
        rpy="0 0 0" />
      <geometry>
        <mesh
          filename="package://my_robot/meshes/RH_HIP.STL" />
      </geometry>
    </collision>
  </link>
  <joint
    name="RH_HAA"
    type="revolute">
    <origin
      xyz="-0.049795 0.054686 0.0044408"
      rpy="1.5708 0 0" />
    <parent
      link="base" />
    <child
      link="RH_HIP" />
    <axis
      xyz="0 0 1" />
    <limit
      lower="-0.35"
      upper="0.35"
      effort="0"
      velocity="0" />
  </joint>
  <link
    name="RH_SHANK">
    <inertial>
      <origin
        xyz="0.0122497084855831 -0.0302194066240428 -0.0224095204785166"
        rpy="0 0 0" />
      <mass
        value="0.0125650044620547" />
      <inertia
        ixx="0"
        ixy="0"
        ixz="0"
        iyy="0"
        iyz="0"
        izz="0" />
    </inertial>
    <visual>
      <origin
        xyz="0 0 0"
        rpy="0 0 0" />
      <geometry>
        <mesh
          filename="package://my_robot/meshes/RH_SHANK.STL" />
      </geometry>
      <material
        name="">
        <color
          rgba="0.792156862745098 0.819607843137255 0.933333333333333 1" />
      </material>
    </visual>
    <collision>
      <origin
        xyz="0 0 0"
        rpy="0 0 0" />
      <geometry>
        <mesh
          filename="package://my_robot/meshes/RH_SHANK.STL" />
      </geometry>
    </collision>
  </link>
  <joint
    name="RH_HFE"
    type="revolute">
    <origin
      xyz="0.015101 -0.012338 -0.0263"
      rpy="0.016319 1.5708 0" />
    <parent
      link="RH_HIP" />
    <child
      link="RH_SHANK" />
    <axis
      xyz="0 0 1" />
    <limit
      lower="-0.524"
      upper="0.524"
      effort="0"
      velocity="0" />
  </joint>
  <link
    name="RH_KNEE">
    <inertial>
      <origin
        xyz="0.00309817982357408 -0.0214406865900601 -0.0203001198707538"
        rpy="0 0 0" />
      <mass
        value="0.0209402145365318" />
      <inertia
        ixx="2.84887560917356E-06"
        ixy="4.57449680635344E-07"
        ixz="6.47675375139834E-08"
        iyy="2.88411284172098E-07"
        iyz="-3.87108439881677E-07"
        izz="2.72321747733031E-06" />
    </inertial>
    <visual>
      <origin
        xyz="0 0 0"
        rpy="0 0 0" />
      <geometry>
        <mesh
          filename="package://my_robot/meshes/RH_KNEE.STL" />
      </geometry>
      <material
        name="">
        <color
          rgba="0.792156862745098 0.819607843137255 0.933333333333333 1" />
      </material>
    </visual>
    <collision>
      <origin
        xyz="0 0 0"
        rpy="0 0 0" />
      <geometry>
        <mesh
          filename="package://my_robot/meshes/RH_KNEE.STL" />
      </geometry>
    </collision>
  </link>
  <joint
    name="RH_KFE"
    type="revolute">
    <origin
      xyz="0.024219 -0.060319 0"
      rpy="1.8962E-18 5.305E-18 -0.8858" />
    <parent
      link="RH_SHANK" />
    <child
      link="RH_KNEE" />
    <axis
      xyz="0 0 1" />
    <limit
      lower="-0.524"
      upper="0.524"
      effort="0"
      velocity="0" />
  </joint>
  <link
    name="RF_HIP">
    <inertial>
      <origin
        xyz="-0.00610260071852686 -0.00465988250374973 0.0213257541110594"
        rpy="0 0 0" />
      <mass
        value="0.0202222351258522" />
      <inertia
        ixx="8.09932423716377E-07"
        ixy="-1.6840233441624E-07"
        ixz="-1.67221801893552E-08"
        iyy="5.36422567176781E-07"
        iyz="-5.61826015528394E-08"
        izz="8.15354003148527E-07" />
    </inertial>
    <visual>
      <origin
        xyz="0 0 0"
        rpy="0 0 0" />
      <geometry>
        <mesh
          filename="package://my_robot/meshes/RF_HIP.STL" />
      </geometry>
      <material
        name="">
        <color
          rgba="0.792156862745098 0.819607843137255 0.933333333333333 1" />
      </material>
    </visual>
    <collision>
      <origin
        xyz="0 0 0"
        rpy="0 0 0" />
      <geometry>
        <mesh
          filename="package://my_robot/meshes/RF_HIP.STL" />
      </geometry>
    </collision>
  </link>
  <joint
    name="RF_HAA"
    type="revolute">
    <origin
      xyz="-0.049795 -0.060264 0.0044408"
      rpy="1.5708 0 0" />
    <parent
      link="base" />
    <child
      link="RF_HIP" />
    <axis
      xyz="0 0 1" />
    <limit
      lower="-0.35"
      upper="0.35"
      effort="0"
      velocity="0" />
  </joint>
  <link
    name="RF_SHANK">
    <inertial>
      <origin
        xyz="0.0122497084855832 -0.0302194066240429 -0.0224095204785166"
        rpy="0 0 0" />
      <mass
        value="0.0125650044620547" />
      <inertia
        ixx="0"
        ixy="0"
        ixz="0"
        iyy="0"
        iyz="0"
        izz="0" />
    </inertial>
    <visual>
      <origin
        xyz="0 0 0"
        rpy="0 0 0" />
      <geometry>
        <mesh
          filename="package://my_robot/meshes/RF_SHANK.STL" />
      </geometry>
      <material
        name="">
        <color
          rgba="0.792156862745098 0.819607843137255 0.933333333333333 1" />
      </material>
    </visual>
    <collision>
      <origin
        xyz="0 0 0"
        rpy="0 0 0" />
      <geometry>
        <mesh
          filename="package://my_robot/meshes/RF_SHANK.STL" />
      </geometry>
    </collision>
  </link>
  <joint
    name="RF_HFE"
    type="revolute">
    <origin
      xyz="0.015101 -0.012338 0.0153"
      rpy="0.016319 1.5708 0" />
    <parent
      link="RF_HIP" />
    <child
      link="RF_SHANK" />
    <axis
      xyz="0 0 1" />
    <limit
      lower="-0.524"
      upper="0.524"
      effort="0"
      velocity="0" />
  </joint>
  <link
    name="RF_KNEE">
    <inertial>
      <origin
        xyz="0.00309817882992422 -0.0214406945203041 -0.0203001242470559"
        rpy="0 0 0" />
      <mass
        value="0.0209402067425756" />
      <inertia
        ixx="2.84887124497832E-06"
        ixy="4.57449944216634E-07"
        ixz="6.47677002811506E-08"
        iyy="2.88410504831284E-07"
        iyz="-3.87106536609186E-07"
        izz="2.72321425283967E-06" />
    </inertial>
    <visual>
      <origin
        xyz="0 0 0"
        rpy="0 0 0" />
      <geometry>
        <mesh
          filename="package://my_robot/meshes/RF_KNEE.STL" />
      </geometry>
      <material
        name="">
        <color
          rgba="0.792156862745098 0.819607843137255 0.933333333333333 1" />
      </material>
    </visual>
    <collision>
      <origin
        xyz="0 0 0"
        rpy="0 0 0" />
      <geometry>
        <mesh
          filename="package://my_robot/meshes/RF_KNEE.STL" />
      </geometry>
    </collision>
  </link>
  <joint
    name="RF_KFE"
    type="revolute">
    <origin
      xyz="0.024219 -0.060319 0"
      rpy="1.3671E-18 1.5629E-18 -0.8858" />
    <parent
      link="RF_SHANK" />
    <child
      link="RF_KNEE" />
    <axis
      xyz="0 0 1" />
    <limit
      lower="-0.524"
      upper="0.524"
      effort="0"
      velocity="0" />
  </joint>
</robot>