<?xml version="1.0"?>
<link name="world"/>

 <joint name="grounding" type="fixed">
    <origin xyz="0 0 0" rpy="0 0 0"></origin>
    <parent link="world"/>
    <child link="outer_ring"/>
  </joint>

  <link
    name="outer_ring">
    <inertial>
      <origin
        xyz="0 2.41110241903461E-18 0.165"
        rpy="0 0 0" />
      <mass
        value="0.49244" />
      <inertia
        ixx="0.00502601319324487"
        ixy="-1.62358744911733E-35"
        ixz="7.47908862031761E-35"
        iyy="0.00502601319324487"
        iyz="-2.39524257656496E-19"
        izz="0.00111415601711858" />
    </inertial>
    <collision>
      <origin
        xyz="0 0 0"
        rpy="1.5707963267949 0 0" />
      <geometry>
        <mesh
          filename="package://walker_gazebo/meshes/outter_ring.STL" />
      </geometry>
    </collision>
  </link>

  <joint name="outer_ring_inner_ring" type="prismatic">
    <origin xyz="0 0 0.330" rpy="0 0 0"></origin>
    <parent link="outer_ring"></parent>
    <child link="inner_ring"></child>
    <axis xyz="0 -1 0"></axis>
    <limit effort="30" lower="0.0" upper="10.0" velocity="7.0"></limit>
    <dynamics damping="0.0" friction="0.0"/>
  </joint>

  <link
    name="inner_ring">
    <inertial>
      <origin
        xyz="1.9888E-21 2.902765522478E-18 0.032744"
        rpy="0 0 0" />
      <mass
        value="0.41592" />
      <inertia
        ixx="0.000359315600962194"
        ixy="-5.5118705611265E-24"
        ixz="3.13347162793032E-23"
        iyy="0.000359274048641079"
        iyz="8.28368014073459E-21"
        izz="0.000418748218163316" />
    </inertial>
    <collision>
      <origin
        xyz="0 0 0"
        rpy="1.5707963267949 0 0" />
      <geometry>
        <mesh
          filename="package://walker_gazebo/meshes/inner_ring.STL" />
      </geometry>
    </collision>
  </link>

  <joint name="inner_ring_boom" type="fixed">
    <origin xyz="0 0 0.080" rpy="0 0 0"></origin>
    <parent link="inner_ring"></parent>
    <child link="boom"></child>
    <axis xyz="0 -1 0"></axis>
  </joint>

  <link
    name="boom">
    <inertial>
      <origin
        xyz="0.33356 4.01527583384352E-18 0.024218"
        rpy="0 0 0" />
      <mass
        value="0.18809" />
      <inertia
        ixx="1.07257686642265E-05"
        ixy="-1.10823505766879E-19"
        ixz="4.90544717612682E-05"
        iyy="0.00892424521805477"
        iyz="-8.28057414299352E-22"
        izz="0.00892212851787082" />
    </inertial>
    <collision>
      <origin
        xyz="0 0 0"
        rpy="1.5707963267949 0 0" />
      <geometry>
        <mesh
          filename="package://walker_gazebo/meshes/boom_horizontal.STL" />
      </geometry>
    </collision>
  </link>

  <gazebo reference="waist">
       <material>Gazebo/Red</material>
    </gazebo>
    <gazebo reference="thighR">
       <material>Gazebo/Blue</material>
    </gazebo>
      <gazebo reference="thighL">
       <material>Gazebo/Blue</material>
    </gazebo>
      <gazebo reference="shankR">
       <material>Gazebo/Red</material>
    </gazebo>
      <gazebo reference="shankL">
       <material>Gazebo/Red</material>
    </gazebo>
      <gazebo reference="footR">
       <material>Gazebo/Black</material>
    </gazebo>
      <gazebo reference="footL">
       <material>Gazebo/Black</material>
    </gazebo>

    <gazebo reference="boom">
       <material>Gazebo/Transparent</material>
    </gazebo>

  <joint name="boom_waist" type="prismatic">
    <origin xyz="0.725 0 0" rpy="0 0 0"></origin>
    <parent link="boom"></parent>
    <child link="waist"></child>
    <axis xyz="0 0 1"></axis>
    <limit effort="30" lower="-0.5" upper="0.5" velocity="7.0"></limit>
    <dynamics damping="0.0" friction="0.0"/>
  </joint>
